Traceback (most recent call last):
  File "/opt/anaconda3/envs/book/lib/python3.8/site-packages/jupyter_cache/executors/utils.py", line 51, in single_nb_execution
    executenb(
  File "/opt/anaconda3/envs/book/lib/python3.8/site-packages/nbclient/client.py", line 1112, in execute
    return NotebookClient(nb=nb, resources=resources, km=km, **kwargs).execute()
  File "/opt/anaconda3/envs/book/lib/python3.8/site-packages/nbclient/util.py", line 74, in wrapped
    return just_run(coro(*args, **kwargs))
  File "/opt/anaconda3/envs/book/lib/python3.8/site-packages/nbclient/util.py", line 53, in just_run
    return loop.run_until_complete(coro)
  File "/opt/anaconda3/envs/book/lib/python3.8/asyncio/base_events.py", line 616, in run_until_complete
    return future.result()
  File "/opt/anaconda3/envs/book/lib/python3.8/site-packages/nbclient/client.py", line 553, in async_execute
    await self.async_execute_cell(
  File "/opt/anaconda3/envs/book/lib/python3.8/site-packages/nbclient/client.py", line 857, in async_execute_cell
    self._check_raise_for_error(cell, exec_reply)
  File "/opt/anaconda3/envs/book/lib/python3.8/site-packages/nbclient/client.py", line 760, in _check_raise_for_error
    raise CellExecutionError.from_cell_and_msg(cell, exec_reply_content)
nbclient.exceptions.CellExecutionError: An error occurred while executing the following cell:
------------------
from matplotlib import pyplot as plt
import numpy as np

# style plots
def write_local_style():
    mpltxt = """patch.linewidth: 0.5\npatch.facecolor: 348ABD  \npatch.edgecolor: EEEEEE\n
    patch.antialiased: True\nlines.solid_capstyle: round\nfont.size: 10.0\n
    font.family: Trebuchet MS\ntext.color: 575757\naxes.facecolor: none\n
    axes.edgecolor: 575757\naxes.spines.left   : True   \naxes.spines.bottom : True\n
    axes.spines.top    : False\naxes.spines.right  : False\naxes.linewidth: 1\naxes.grid: True\n
    axes.titlesize: x-large\naxes.labelsize: large\naxes.labelcolor: 575757\naxes.axisbelow: True       \n
    axes.prop_cycle: cycler('color', ['29ba74', '6e6f73', '295e7e', '670f31', '98b21c', '9a9a9a', '3ead92'])\n
    xtick.color: 575757\nxtick.direction: out\nxtick.labelsize : medium\nxtick.major.width: 1\n
    xtick.major.size: 4      \nytick.color: 575757\nytick.direction: out\nytick.labelsize : medium\n
    ytick.major.width: 1\nytick.major.size: 4\ngrid.color: none\nfigure.facecolor: none\n
    figure.edgecolor: 0.50\nfigure.dpi: 150      \n"""
    with open('data/style/mystyle.mplstyle','w+') as f:
        f.write(mpltxt)

write_local_style()
plt.style.use('data/style/mystyle.mplstyle')
------------------

[0;31m---------------------------------------------------------------------------[0m
[0;31mModuleNotFoundError[0m                       Traceback (most recent call last)
[0;32m<ipython-input-4-2773c532c10c>[0m in [0;36m<module>[0;34m[0m
[0;32m----> 1[0;31m [0;32mfrom[0m [0mmatplotlib[0m [0;32mimport[0m [0mpyplot[0m [0;32mas[0m [0mplt[0m[0;34m[0m[0;34m[0m[0m
[0m[1;32m      2[0m [0;32mimport[0m [0mnumpy[0m [0;32mas[0m [0mnp[0m[0;34m[0m[0;34m[0m[0m
[1;32m      3[0m [0;34m[0m[0m
[1;32m      4[0m [0;31m# style plots[0m[0;34m[0m[0;34m[0m[0;34m[0m[0m
[1;32m      5[0m [0;32mdef[0m [0mwrite_local_style[0m[0;34m([0m[0;34m)[0m[0;34m:[0m[0;34m[0m[0;34m[0m[0m

[0;31mModuleNotFoundError[0m: No module named 'matplotlib'
ModuleNotFoundError: No module named 'matplotlib'

